Workbook

Sheet INVENTARIO
B1: PROCESO/PROCEDIMIENTO | P1: CLASIFICACIÓN | S1: CRITICIDAD
A2: ID | B2: TIPO DE PROCESO | C2: TIPO DE MACROPROCESO | D2: CODIGO MACROPROCESO | E2: PROCESO | F2: SUBPROCESO | G2: PROCEDIMIENTO | H2: NOMBRE | I2: DESCRIPCIÓN | J2: RESPONSABLE | K2: CUSTODIO | L2: UBICACIÓN | M2: MEDIO DE CONSERVACIÓN | N2: TIPO DE ACTIVO | O2: CATEGORÍA | P2: CONFIDENCIALIDAD | Q2: INTEGRIDAD | R2: DISPONIBILIDAD | S2: VALORACION | T2: CRITICIDAD | U2: ACCESO EXTERNO | V2: FECHA DE REGISTRO | W2: FECHA DE SALIDA | X2: RIESGO EVALUADO
A3: 1-GAD | B3: APOYO | C3: Gestión Administrativa | D3: GAD | E3: Comunicación y Asistencia Gerencial | F3: - | G3: Recepción y registro de documentos | H3: Matriz de control de documentos Gerencia | I3: Reporte que genera el sistema Ventanilla Virtual - Administra Procesos y opera la S de Gerencia | J3: Secretaria de Gerencia General | K3: Secretaria de Gerencia General | L3: UBICACIÓN DIGITAL-EQUIPO DEL RESPONSABLE | M3: DISCOS DUROS, SERVIDORES, DISCOS O MEDIOS PORTÁTILES, CINTAS O MEDIOS DE VIDEO Y AUDIO, ETC. | N3: PRIMARIOS | O3: DOCUMENTOS TÉCNICOS | P3: USO INTERNO(2) | Q3: BAJA(1) | R3: BAJA(1) | S3: =+(IF(P3="PUBLICA(1)",1,IF(P3="USO INTERNO(2)",2,IF(P3="RESTRINGIDO(3)",3,3))))+(IF(Q3="BAJA(1)",1,IF(Q3="MEDIA(2)",2,IF(Q3="ALTA(3)",3,3))))+(IF(R3="BAJA(1)",1,IF(R3="MEDIA(2)",2,IF(R3="ALTA(3)",3,3)))) | T3: =+IF(S3<6,"BAJA",IF(S3<8,"MEDIA","ALTA")) | U3: - | V3: 45673 | W3: N/A | X3: =+IFERROR(IF(VLOOKUP(Tabla2[[#This Row],[ID]],'EVALUACION DE RIESGO'!A:A,1,FALSE)=Tabla2[[#This Row],[ID]],"SI","NO"),"NO")
A4: 2-GAD | B4: APOYO | C4: Gestión Administrativa | D4: GAD | E4: Comunicación y Asistencia Gerencial | F4: - | G4: Recepción y registro de documentos | H4: Registro de entrega recepción de documentos | I4: Recepción de archivos físicos como digitales | J4: Secretaria de Gerencia General | K4: Secretaria de Gerencia General | L4: UBICACIÓN FISICA-MATRIZ ATUNTAQUI | M4: DOCUMENTO DE ARCHIVO-FÍSICO | N4: PRIMARIOS | O4: DOCUMENTOS HABILITANTES | P4: USO INTERNO(2) | Q4: BAJA(1) | R4: BAJA(1) | S4: =+(IF(P4="PUBLICA(1)",1,IF(P4="USO INTERNO(2)",2,IF(P4="RESTRINGIDO(3)",3,3))))+(IF(Q4="BAJA(1)",1,IF(Q4="MEDIA(2)",2,IF(Q4="ALTA(3)",3,3))))+(IF(R4="BAJA(1)",1,IF(R4="MEDIA(2)",2,IF(R4="ALTA(3)",3,3)))) | T4: =+IF(S4<6,"BAJA",IF(S4<8,"MEDIA","ALTA")) | U4: - | V4: 45673 | W4: N/A | X4: =+IFERROR(IF(VLOOKUP(Tabla2[[#This Row],[ID]],'EVALUACION DE RIESGO'!A:A,1,FALSE)=Tabla2[[#This Row],[ID]],"SI","NO"),"NO")
A5: 3-GAD | B5: APOYO | C5: Gestión Administrativa | D5: GAD | E5: Comunicación y Asistencia Gerencial | F5: - | G5: Seguimiento y cierre de trámites | H5: Matriz de control de documentos Gerencia (Seguimiento) | I5: Matriz de control de documentos Gerencia | J5: Secretaria de Gerencia General | K5: Secretaria de Gerencia General | L5: UBICACIÓN DIGITAL-EQUIPO DEL RESPONSABLE | M5: DISCOS DUROS, SERVIDORES, DISCOS O MEDIOS PORTÁTILES, CINTAS O MEDIOS DE VIDEO Y AUDIO, ETC. | N5: PRIMARIOS | O5: DOCUMENTOS TÉCNICOS | P5: USO INTERNO(2) | Q5: MEDIA(2) | R5: BAJA(1) | S5: =+(IF(P5="PUBLICA(1)",1,IF(P5="USO INTERNO(2)",2,IF(P5="RESTRINGIDO(3)",3,3))))+(IF(Q5="BAJA(1)",1,IF(Q5="MEDIA(2)",2,IF(Q5="ALTA(3)",3,3))))+(IF(R5="BAJA(1)",1,IF(R5="MEDIA(2)",2,IF(R5="ALTA(3)",3,3)))) | T5: =+IF(S5<6,"BAJA",IF(S5<8,"MEDIA","ALTA")) | U5: - | V5: 45673 | W5: N/A | X5: =+IFERROR(IF(VLOOKUP(Tabla2[[#This Row],[ID]],'EVALUACION DE RIESGO'!A:A,1,FALSE)=Tabla2[[#This Row],[ID]],"SI","NO"),"NO")
A6: 4-GAD | B6: APOYO | C6: Gestión Administrativa | D6: GAD | E6: Comunicación y Asistencia Gerencial | F6: - | G6: Despacho de oficios generados en otras áreas | H6: Oficio Memorandos | I6: Archivos físicos como digitales de Gerencia | J6: Secretaria de Gerencia General | K6: Secretaria de Gerencia General | L6: UBICACIÓN DIGITAL-EQUIPO DEL RESPONSABLE | M6: DOCUMENTO DE ARCHIVO-FÍSICO | N6: PRIMARIOS | O6: DOCUMENTOS HABILITANTES | P6: RESTRINGIDO(3) | Q6: BAJA(1) | R6: MEDIA(2) | S6: =+(IF(P6="PUBLICA(1)",1,IF(P6="USO INTERNO(2)",2,IF(P6="RESTRINGIDO(3)",3,3))))+(IF(Q6="BAJA(1)",1,IF(Q6="MEDIA(2)",2,IF(Q6="ALTA(3)",3,3))))+(IF(R6="BAJA(1)",1,IF(R6="MEDIA(2)",2,IF(R6="ALTA(3)",3,3)))) | T6: =+IF(S6<6,"BAJA",IF(S6<8,"MEDIA","ALTA")) | U6: - | V6: 45673 | W6: N/A | X6: =+IFERROR(IF(VLOOKUP(Tabla2[[#This Row],[ID]],'EVALUACION DE RIESGO'!A:A,1,FALSE)=Tabla2[[#This Row],[ID]],"SI","NO"),"NO")
A7: 5-GAD | B7: APOYO | C7: Gestión Administrativa | D7: GAD | E7: Comunicación y Asistencia Gerencial | F7: - | G7: Manejo de Agenda | H7: Agenda gerencial | I7: Reporte mensual que se presenta a gerencia | J7: Secretaria de Gerencia General | K7: Secretaria de Gerencia General | L7: UBICACIÓN DIGITAL-EQUIPO DEL RESPONSABLE | M7: DISCOS DUROS, SERVIDORES, DISCOS O MEDIOS PORTÁTILES, CINTAS O MEDIOS DE VIDEO Y AUDIO, ETC. | N7: PRIMARIOS | O7: DOCUMENTOS TÉCNICOS | P7: RESTRINGIDO(3) | Q7: MEDIA(2) | R7: BAJA(1) | S7: =+(IF(P7="PUBLICA(1)",1,IF(P7="USO INTERNO(2)",2,IF(P7="RESTRINGIDO(3)",3,3))))+(IF(Q7="BAJA(1)",1,IF(Q7="MEDIA(2)",2,IF(Q7="ALTA(3)",3,3))))+(IF(R7="BAJA(1)",1,IF(R7="MEDIA(2)",2,IF(R7="ALTA(3)",3,3)))) | T7: =+IF(S7<6,"BAJA",IF(S7<8,"MEDIA","ALTA")) | U7: - | V7: 45673 | W7: N/A | X7: =+IFERROR(IF(VLOOKUP(Tabla2[[#This Row],[ID]],'EVALUACION DE RIESGO'!A:A,1,FALSE)=Tabla2[[#This Row],[ID]],"SI","NO"),"NO")
A8: 6-GAD | B8: APOYO | C8: Gestión Administrativa | D8: GAD | E8: Comunicación y Asistencia Gerencial | F8: - | G8: N/A | H8: Archivo de Secretaria de Gerencia | I8: Archivos físicos que reposan en el archivo del área | J8: Secretaria de Gerencia General | K8: Secretaria de Gerencia General | L8: DOCUMENTOS FISICOS-ARCHIVOS DE LA OFICINA | M8: DOCUMENTO DE ARCHIVO-FÍSICO | N8: PRIMARIOS | O8: DOCUMENTOS HABILITANTES | P8: RESTRINGIDO(3) | Q8: MEDIA(2) | R8: MEDIA(2) | S8: =+(IF(P8="PUBLICA(1)",1,IF(P8="USO INTERNO(2)",2,IF(P8="RESTRINGIDO(3)",3,3))))+(IF(Q8="BAJA(1)",1,IF(Q8="MEDIA(2)",2,IF(Q8="ALTA(3)",3,3))))+(IF(R8="BAJA(1)",1,IF(R8="MEDIA(2)",2,IF(R8="ALTA(3)",3,3)))) | T8: =+IF(S8<6,"BAJA",IF(S8<8,"MEDIA","ALTA")) | U8: - | V8: 45673 | W8: N/A | X8: =+IFERROR(IF(VLOOKUP(Tabla2[[#This Row],[ID]],'EVALUACION DE RIESGO'!A:A,1,FALSE)=Tabla2[[#This Row],[ID]],"SI","NO"),"NO")
A9: 7-GAD | B9: APOYO | C9: Gestión Administrativa | D9: GAD | E9: Comunicación y Asistencia Gerencial | F9: - | G9: N/A | H9: Equipos de computación de Asistente de Gerencia | I9: Equipos de computación donde se realiza la gestión del área | J9: Secretaria de Gerencia General | K9: Secretaria de Gerencia General | L9: DOCUMENTOS FISICOS-ARCHIVOS DE LA OFICINA | M9: DOCUMENTO DE ARCHIVO-FÍSICO | N9: APOYO | O9: HARDWARE | P9: USO INTERNO(2) | Q9: BAJA(1) | R9: MEDIA(2) | S9: =+(IF(P9="PUBLICA(1)",1,IF(P9="USO INTERNO(2)",2,IF(P9="RESTRINGIDO(3)",3,3))))+(IF(Q9="BAJA(1)",1,IF(Q9="MEDIA(2)",2,IF(Q9="ALTA(3)",3,3))))+(IF(R9="BAJA(1)",1,IF(R9="MEDIA(2)",2,IF(R9="ALTA(3)",3,3)))) | T9: =+IF(S9<6,"BAJA",IF(S9<8,"MEDIA","ALTA")) | U9: - | V9: 45673 | W9: N/A | X9: =+IFERROR(IF(VLOOKUP(Tabla2[[#This Row],[ID]],'EVALUACION DE RIESGO'!A:A,1,FALSE)=Tabla2[[#This Row],[ID]],"SI","NO"),"NO")
A10: 8-GAD | B10: APOYO | C10: Gestión Administrativa | D10: GAD | E10: Comunicación y Asistencia Gerencial | F10: - | G10: N/A | H10: Asistente de Gerencia | I10: N/A | J10: Secretaria de Gerencia General | K10: Secretaria de Gerencia General | L10: N/A | M10: N/A | N10: APOYO | O10: RECURSO HUMANO | P10: USO INTERNO(2) | Q10: BAJA(1) | R10: MEDIA(2) | S10: =+(IF(P10="PUBLICA(1)",1,IF(P10="USO INTERNO(2)",2,IF(P10="RESTRINGIDO(3)",3,3))))+(IF(Q10="BAJA(1)",1,IF(Q10="MEDIA(2)",2,IF(Q10="ALTA(3)",3,3))))+(IF(R10="BAJA(1)",1,IF(R10="MEDIA(2)",2,IF(R10="ALTA(3)",3,3)))) | T10: =+IF(S10<6,"BAJA",IF(S10<8,"MEDIA","ALTA")) | U10: - | V10: 45673 | W10: N/A | X10: =+IFERROR(IF(VLOOKUP(Tabla2[[#This Row],[ID]],'EVALUACION DE RIESGO'!A:A,1,FALSE)=Tabla2[[#This Row],[ID]],"SI","NO"),"NO")
A11: 9-GAD | B11: APOYO | C11: Gestión Administrativa | D11: GAD | E11: Gestión de Activos | F11: - | G11: Registro de activos fijos | H11: Documentos habilitantes | I11: Documentos recibidos de activos fijos adquiridos, no almacena en un repositorio porque toda la información del activo se registra en FIT, serie, marca, modelo, color, custodio, oficina de destino, ubicación de la oficina. | J11: Jefe Administrativo | K11: Jefe Administrativo | L11: UBICACIÓN DIGITAL-EQUIPO DEL CUSTODIO | M11: DISCOS DUROS, SERVIDORES, DISCOS O MEDIOS PORTÁTILES, CINTAS O MEDIOS DE VIDEO Y AUDIO, ETC. | N11: PRIMARIOS | O11: DOCUMENTOS HABILITANTES | P11: PUBLICA(1) | Q11: BAJA(1) | R11: MEDIA(2) | S11: =+(IF(P11="PUBLICA(1)",1,IF(P11="USO INTERNO(2)",2,IF(P11="RESTRINGIDO(3)",3,3))))+(IF(Q11="BAJA(1)",1,IF(Q11="MEDIA(2)",2,IF(Q11="ALTA(3)",3,3))))+(IF(R11="BAJA(1)",1,IF(R11="MEDIA(2)",2,IF(R11="ALTA(3)",3,3)))) | T11: =+IF(S11<6,"BAJA",IF(S11<8,"MEDIA","ALTA")) | U11: - | V11: 45680 | W11: N/A | X11: =+IFERROR(IF(VLOOKUP(Tabla2[[#This Row],[ID]],'EVALUACION DE RIESGO'!A:A,1,FALSE)=Tabla2[[#This Row],[ID]],"SI","NO"),"NO")
A12: 10-GAD | B12: APOYO | C12: Gestión Administrativa | D12: GAD | E12: Gestión de Activos | F12: - | G12: Planificación de mantenimientos | H12: Informe de mantenimiento | I12: Informe de avances de la planificación realizada con detalles de descripción, elementos, actividad, área ubicación de mantenimiento, cantidad, observación, cronograma cumplido | J12: Jefe Administrativo | K12: Jefe Administrativo | L12: UBICACIÓN DIGITAL-EQUIPO DEL CUSTODIO | M12: DISCOS DUROS, SERVIDORES, DISCOS O MEDIOS PORTÁTILES, CINTAS O MEDIOS DE VIDEO Y AUDIO, ETC. | N12: PRIMARIOS | O12: DOCUMENTOS HABILITANTES | P12: PUBLICA(1) | Q12: BAJA(1) | R12: MEDIA(2) | S12: =+(IF(P12="PUBLICA(1)",1,IF(P12="USO INTERNO(2)",2,IF(P12="RESTRINGIDO(3)",3,3))))+(IF(Q12="BAJA(1)",1,IF(Q12="MEDIA(2)",2,IF(Q12="ALTA(3)",3,3))))+(IF(R12="BAJA(1)",1,IF(R12="MEDIA(2)",2,IF(R12="ALTA(3)",3,3)))) | T12: =+IF(S12<6,"BAJA",IF(S12<8,"MEDIA","ALTA")) | U12: - | V12: 45680 | W12: N/A | X12: =+IFERROR(IF(VLOOKUP(Tabla2[[#This Row],[ID]],'EVALUACION DE RIESGO'!A:A,1,FALSE)=Tabla2[[#This Row],[ID]],"SI","NO"),"NO")
A13: 11-GAD | B13: APOYO | C13: Gestión Administrativa | D13: GAD | E13: Gestión de Activos | F13: - | G13: Planificación de mantenimientos | H13: Cronograma/Bitácora de mantenimiento | I13: Archivo de planificación que contiene descripción, elementos, actividad, área ubicación de mantenimiento, cantidad, observación, cronograma cumplido | J13: Jefe Administrativo | K13: Jefe Administrativo | L13: UBICACIÓN DIGITAL-EQUIPO DEL CUSTODIO | M13: DISCOS DUROS, SERVIDORES, DISCOS O MEDIOS PORTÁTILES, CINTAS O MEDIOS DE VIDEO Y AUDIO, ETC. | N13: PRIMARIOS | O13: DOCUMENTOS TÉCNICOS | P13: PUBLICA(1) | Q13: BAJA(1) | R13: MEDIA(2) | S13: =+(IF(P13="PUBLICA(1)",1,IF(P13="USO INTERNO(2)",2,IF(P13="RESTRINGIDO(3)",3,3))))+(IF(Q13="BAJA(1)",1,IF(Q13="MEDIA(2)",2,IF(Q13="ALTA(3)",3,3))))+(IF(R13="BAJA(1)",1,IF(R13="MEDIA(2)",2,IF(R13="ALTA(3)",3,3)))) | T13: =+IF(S13<6,"BAJA",IF(S13<8,"MEDIA","ALTA")) | U13: - | V13: 45680 | W13: N/A | X13: =+IFERROR(IF(VLOOKUP(Tabla2[[#This Row],[ID]],'EVALUACION DE RIESGO'!A:A,1,FALSE)=Tabla2[[#This Row],[ID]],"SI","NO"),"NO")
A14: 12-GAD | B14: APOYO | C14: Gestión Administrativa | D14: GAD | E14: Gestión de Activos | F14: - | G14: Mantenimiento preventivo de bienes e inmuebles | H14: Solicitud de adquisiciones y contratación | I14: solicitudes que se gestionan en el sistema Sara con información de número de solicitud, requerimiento, justificación de la adquisición, bienes y servicio, información del plan anual, fechas inicio de proceso, documentos anexos, TDR | J14: Jefe Administrativo | K14: Jefe Administrativo | L14: UBICACIÓN DIGITAL-EQUIPO DEL CUSTODIO | M14: DISCOS DUROS, SERVIDORES, DISCOS O MEDIOS PORTÁTILES, CINTAS O MEDIOS DE VIDEO Y AUDIO, ETC. | N14: PRIMARIOS | O14: DOCUMENTOS HABILITANTES | P14: PUBLICA(1) | Q14: BAJA(1) | R14: MEDIA(2) | S14: =+(IF(P14="PUBLICA(1)",1,IF(P14="USO INTERNO(2)",2,IF(P14="RESTRINGIDO(3)",3,3))))+(IF(Q14="BAJA(1)",1,IF(Q14="MEDIA(2)",2,IF(Q14="ALTA(3)",3,3))))+(IF(R14="BAJA(1)",1,IF(R14="MEDIA(2)",2,IF(R14="ALTA(3)",3,3)))) | T14: =+IF(S14<6,"BAJA",IF(S14<8,"MEDIA","ALTA")) | U14: - | V14: 45680 | W14: N/A | X14: =+IFERROR(IF(VLOOKUP(Tabla2[[#This Row],[ID]],'EVALUACION DE RIESGO'!A:A,1,FALSE)=Tabla2[[#This Row],[ID]],"SI","NO"),"NO")
... A241: 66-GCA | B241: PRODUCTIVO | C241: Gestión de Captaciones | D241: GCA | E241: N/A | F241: - | G241: N/A | H241: Jefe de Captaciones | I241: N/A | J241: Jefe de Captaciones | K241: N/A | L241: N/A | M241: N/A | N241: APOYO | O241: RECURSO HUMANO | P241: USO INTERNO(2) | Q241: MEDIA(2) | R241: MEDIA(2) | S241: =+(IF(P241="PUBLICA(1)",1,IF(P241="USO INTERNO(2)",2,IF(P241="RESTRINGIDO(3)",3,3))))+(IF(Q241="BAJA(1)",1,IF(Q241="MEDIA(2)",2,IF(Q241="ALTA(3)",3,3))))+(IF(R241="BAJA(1)",1,IF(R241="MEDIA(2)",2,IF(R241="ALTA(3)",3,3)))) | T241: =+IF(S241<6,"BAJA",IF(S241<8,"MEDIA","ALTA")) | U241: - | V241: 45712 | W241: N/A | X241: =+IFERROR(IF(VLOOKUP(Tabla2[[#This Row],[ID]],'EVALUACION DE RIESGO'!A:A,1,FALSE)=Tabla2[[#This Row],[ID]],"SI","NO"),"NO")
A242: 1-GCO | B242: PRODUCTIVO | C242: Gestión de Colocaciones | D242: GCO | E242: Gestión de Crédito de Consumo | F242: - | G242: Solicitud de crédito | H242: File de crédito | I242: File digital que contiene toda la documentación referente a los lineamientos del tipo de crédito | J242: Jefe de Negocios | K242: FIT | L242: UBICACIÓN DIGITAL-CORE FINANCIERO | M242: DOCUMENTO DE ARCHIVO-ELECTRÓNICO | N242: PRIMARIOS | O242: INFORMACIÓN DE SOCIOS Y CLIENTES | P242: RESTRINGIDO(3) | Q242: MEDIA(2) | R242: MEDIA(2) | S242: =+(IF(P242="PUBLICA(1)",1,IF(P242="USO INTERNO(2)",2,IF(P242="RESTRINGIDO(3)",3,3))))+(IF(Q242="BAJA(1)",1,IF(Q242="MEDIA(2)",2,IF(Q242="ALTA(3)",3,3))))+(IF(R242="BAJA(1)",1,IF(R242="MEDIA(2)",2,IF(R242="ALTA(3)",3,3)))) | T242: =+IF(S242<6,"BAJA",IF(S242<8,"MEDIA","ALTA")) | U242: - | V242: 8/02/225 | W242: N/A | X242: =+IFERROR(IF(VLOOKUP(Tabla2[[#This Row],[ID]],'EVALUACION DE RIESGO'!A:A,1,FALSE)=Tabla2[[#This Row],[ID]],"SI","NO"),"NO")
A243: 2-GCO | B243: PRODUCTIVO | C243: Gestión de Colocaciones | D243: GCO | E243: Gestión de Crédito de Consumo | F243: - | G243: Solicitud de créditos con garantía de plazo fijo | H243: File de crédito / Certificado del DPF | I243: File digital que contiene toda la documentación referente a los lineamientos del tipo de crédito, de adjunta la copia del DPF | J243: Jefe de Negocios | K243: FIT | L243: UBICACIÓN DIGITAL-CORE FINANCIERO | M243: DOCUMENTO DE ARCHIVO-ELECTRÓNICO | N243: PRIMARIOS | O243: INFORMACIÓN DE SOCIOS Y CLIENTES | P243: RESTRINGIDO(3) | Q243: MEDIA(2) | R243: MEDIA(2) | S243: =+(IF(P243="PUBLICA(1)",1,IF(P243="USO INTERNO(2)",2,IF(P243="RESTRINGIDO(3)",3,3))))+(IF(Q243="BAJA(1)",1,IF(Q243="MEDIA(2)",2,IF(Q243="ALTA(3)",3,3))))+(IF(R243="BAJA(1)",1,IF(R243="MEDIA(2)",2,IF(R243="ALTA(3)",3,3)))) | T243: =+IF(S243<6,"BAJA",IF(S243<8,"MEDIA","ALTA")) | U243: - | V243: 8/02/225 | W243: N/A | X243: =+IFERROR(IF(VLOOKUP(Tabla2[[#This Row],[ID]],'EVALUACION DE RIESGO'!A:A,1,FALSE)=Tabla2[[#This Row],[ID]],"SI","NO"),"NO")
A244: 3-GCO | B244: PRODUCTIVO | C244: Gestión de Colocaciones | D244: GCO | E244: Gestión de Crédito de Consumo | F244: - | G244: Solicitud de créditos con garantía prendaria de Oro | H244: File de crédito | I244: File digital que contiene toda la documentación referente a los lineamientos del tipo de crédito | J244: Jefe de Negocios | K244: FIT | L244: UBICACIÓN DIGITAL-CORE FINANCIERO | M244: DOCUMENTO DE ARCHIVO-ELECTRÓNICO | N244: PRIMARIOS | O244: INFORMACIÓN DE SOCIOS Y CLIENTES | P244: USO INTERNO(2) | Q244: MEDIA(2) | R244: MEDIA(2) | S244: =+(IF(P244="PUBLICA(1)",1,IF(P244="USO INTERNO(2)",2,IF(P244="RESTRINGIDO(3)",3,3))))+(IF(Q244="BAJA(1)",1,IF(Q244="MEDIA(2)",2,IF(Q244="ALTA(3)",3,3))))+(IF(R244="BAJA(1)",1,IF(R244="MEDIA(2)",2,IF(R244="ALTA(3)",3,3)))) | T244: =+IF(S244<6,"BAJA",IF(S244<8,"MEDIA","ALTA")) | U244: - | V244: 8/02/225 | W244: N/A | X244: =+IFERROR(IF(VLOOKUP(Tabla2[[#This Row],[ID]],'EVALUACION DE RIESGO'!A:A,1,FALSE)=Tabla2[[#This Row],[ID]],"SI","NO"),"NO")
A245: 4-GCO | B245: PRODUCTIVO | C245: Gestión de Colocaciones | D245: GCO | E245: Gestión de Crédito de Consumo | F245: - | G245: Solicitud de créditos con garantía prendaria de Oro | H245: Prenda de oro | I245: Prenda de garantía que se recibe para otorgar el crédito | J245: Jefe de Negocios | K245: Supervisor Operativo | L245: DOCUMENTOS FISICOS-ARCHIVOS DE LA OFICINA | M245: DOCUMENTO DE ARCHIVO-FÍSICO | N245: PRIMARIOS | O245: INFORMACIÓN DE SOCIOS Y CLIENTES | P245: USO INTERNO(2) | Q245: MEDIA(2) | R245: MEDIA(2) | S245: =+(IF(P245="PUBLICA(1)",1,IF(P245="USO INTERNO(2)",2,IF(P245="RESTRINGIDO(3)",3,3))))+(IF(Q245="BAJA(1)",1,IF(Q245="MEDIA(2)",2,IF(Q245="ALTA(3)",3,3))))+(IF(R245="BAJA(1)",1,IF(R245="MEDIA(2)",2,IF(R245="ALTA(3)",3,3)))) | T245: =+IF(S245<6,"BAJA",IF(S245<8,"MEDIA","ALTA")) | U245: - | V245: 8/02/225 | W245: N/A | X245: =+IFERROR(IF(VLOOKUP(Tabla2[[#This Row],[ID]],'EVALUACION DE RIESGO'!A:A,1,FALSE)=Tabla2[[#This Row],[ID]],"SI","NO"),"NO")
A246: 5-GCO | B246: PRODUCTIVO | C246: Gestión de Colocaciones | D246: GCO | E246: Gestión de Crédito de Consumo | F246: - | G246: Solicitud de créditos con garantía prendaria de Oro | H246: Formulario y foro de la prenda para custodia | I246: Acta entrega que se realiza para la recepción de la prenda | J246: Jefe de Negocios | K246: FIT | L246: UBICACIÓN DIGITAL-CORE FINANCIERO | M246: DOCUMENTO DE ARCHIVO-ELECTRÓNICO | N246: PRIMARIOS | O246: DOCUMENTOS HABILITANTES | P246: USO INTERNO(2) | Q246: MEDIA(2) | R246: MEDIA(2) | S246: =+(IF(P246="PUBLICA(1)",1,IF(P246="USO INTERNO(2)",2,IF(P246="RESTRINGIDO(3)",3,3))))+(IF(Q246="BAJA(1)",1,IF(Q246="MEDIA(2)",2,IF(Q246="ALTA(3)",3,3))))+(IF(R246="BAJA(1)",1,IF(R246="MEDIA(2)",2,IF(R246="ALTA(3)",3,3)))) | T246: =+IF(S246<6,"BAJA",IF(S246<8,"MEDIA","ALTA")) | U246: - | V246: 8/02/225 | W246: N/A | X246: =+IFERROR(IF(VLOOKUP(Tabla2[[#This Row],[ID]],'EVALUACION DE RIESGO'!A:A,1,FALSE)=Tabla2[[#This Row],[ID]],"SI","NO"),"NO")
A247: 6-GCO | B247: PRODUCTIVO | C247: Gestión de Colocaciones | D247: GCO | E247: Gestión de Crédito de Consumo | F247: - | G247: Solicitud de novación, refinanciamiento, o reestructuración de créditos | H247: File de crédito / Informe de análisis de novación, refinanciamiento y restructuración | I247: File digital que contiene toda la documentación referente a los lineamientos del tipo de crédito / el informe de análisis se adjunta al file del crédito | J247: Jefe de Negocios | K247: FIT | L247: UBICACIÓN DIGITAL-CORE FINANCIERO | M247: DOCUMENTO DE ARCHIVO-ELECTRÓNICO | N247: PRIMARIOS | O247: INFORMACIÓN DE SOCIOS Y CLIENTES | P247: RESTRINGIDO(3) | Q247: MEDIA(2) | R247: MEDIA(2) | S247: =+(IF(P247="PUBLICA(1)",1,IF(P247="USO INTERNO(2)",2,IF(P247="RESTRINGIDO(3)",3,3))))+(IF(Q247="BAJA(1)",1,IF(Q247="MEDIA(2)",2,IF(Q247="ALTA(3)",3,3))))+(IF(R247="BAJA(1)",1,IF(R247="MEDIA(2)",2,IF(R247="ALTA(3)",3,3)))) | T247: =+IF(S247<6,"BAJA",IF(S247<8,"MEDIA","ALTA")) | U247: - | V247: 8/02/225 | W247: N/A | X247: =+IFERROR(IF(VLOOKUP(Tabla2[[#This Row],[ID]],'EVALUACION DE RIESGO'!A:A,1,FALSE)=Tabla2[[#This Row],[ID]],"SI","NO"),"NO")
A248: 7-GCO | B248: PRODUCTIVO | C248: Gestión de Colocaciones | D248: GCO | E248: Gestión de Crédito de Consumo | F248: - | G248: Seguimiento al destino del crédito | H248: Formulario de destino del crédito | I248: Formulario de detalle del destino de la solicitud del crédito | J248: Jefe de Negocios | K248: FIT | L248: UBICACIÓN DIGITAL-CORE FINANCIERO | M248: DOCUMENTO DE ARCHIVO-ELECTRÓNICO | N248: PRIMARIOS | O248: INFORMACIÓN DE SOCIOS Y CLIENTES | P248: USO INTERNO(2) | Q248: MEDIA(2) | R248: MEDIA(2) | S248: =+(IF(P248="PUBLICA(1)",1,IF(P248="USO INTERNO(2)",2,IF(P248="RESTRINGIDO(3)",3,3))))+(IF(Q248="BAJA(1)",1,IF(Q248="MEDIA(2)",2,IF(Q248="ALTA(3)",3,3))))+(IF(R248="BAJA(1)",1,IF(R248="MEDIA(2)",2,IF(R248="ALTA(3)",3,3)))) | T248: =+IF(S248<6,"BAJA",IF(S248<8,"MEDIA","ALTA")) | U248: - | V248: 8/02/225 | W248: N/A | X248: =+IFERROR(IF(VLOOKUP(Tabla2[[#This Row],[ID]],'EVALUACION DE RIESGO'!A:A,1,FALSE)=Tabla2[[#This Row],[ID]],"SI","NO"),"NO")
A249: 8-GCO | B249: PRODUCTIVO | C249: Gestión de Colocaciones | D249: GCO | E249: Gestión de PYMES | F249: - | G249: Solicitud de crédito PYME | H249: File de crédito / Formulario previo al otorgamiento del crédito | I249: File digital que contiene toda la documentación referente a los lineamientos del tipo de crédito / el formulario previo se adjunta al otorgamiento del crédito | J249: Gerente de Negocios | K249: FIT | L249: UBICACIÓN DIGITAL-CORE FINANCIERO | M249: DOCUMENTO DE ARCHIVO-ELECTRÓNICO | N249: PRIMARIOS | O249: INFORMACIÓN DE SOCIOS Y CLIENTES | P249: RESTRINGIDO(3) | Q249: MEDIA(2) | R249: MEDIA(2) | S249: =+(IF(P249="PUBLICA(1)",1,IF(P249="USO INTERNO(2)",2,IF(P249="RESTRINGIDO(3)",3,3))))+(IF(Q249="BAJA(1)",1,IF(Q249="MEDIA(2)",2,IF(Q249="ALTA(3)",3,3))))+(IF(R249="BAJA(1)",1,IF(R249="MEDIA(2)",2,IF(R249="ALTA(3)",3,3)))) | T249: =+IF(S249<6,"BAJA",IF(S249<8,"MEDIA","ALTA")) | U249: - | V249: 8/02/225 | W249: N/A | X249: =+IFERROR(IF(VLOOKUP(Tabla2[[#This Row],[ID]],'EVALUACION DE RIESGO'!A:A,1,FALSE)=Tabla2[[#This Row],[ID]],"SI","NO"),"NO")
A250: 9-GCO | B250: PRODUCTIVO | C250: Gestión de Colocaciones | D250: GCO | E250: Gestión de PYMES | F250: - | G250: Solicitud de novación, refinanciamiento, o reestructuración de créditos PYME | H250: File de crédito / Informe de análisis de novación, refinanciamiento y restructuración | I250: File digital que contiene toda la documentación referente a los lineamientos del tipo de crédito / el Informe de análisis de novación, refinanciamiento y restructuración se adjunta al file del crédito | J250: Gerente de Negocios | K250: FIT | L250: UBICACIÓN DIGITAL-CORE FINANCIERO | M250: DOCUMENTO DE ARCHIVO-ELECTRÓNICO | N250: PRIMARIOS | O250: INFORMACIÓN DE SOCIOS Y CLIENTES | P250: RESTRINGIDO(3) | Q250: MEDIA(2) | R250: MEDIA(2) | S250: =+(IF(P250="PUBLICA(1)",1,IF(P250="USO INTERNO(2)",2,IF(P250="RESTRINGIDO(3)",3,3))))+(IF(Q250="BAJA(1)",1,IF(Q250="MEDIA(2)",2,IF(Q250="ALTA(3)",3,3))))+(IF(R250="BAJA(1)",1,IF(R250="MEDIA(2)",2,IF(R250="ALTA(3)",3,3)))) | T250: =+IF(S250<6,"BAJA",IF(S250<8,"MEDIA","ALTA")) | U250: - | V250: 8/02/225 | W250: N/A | X250: =+IFERROR(IF(VLOOKUP(Tabla2[[#This Row],[ID]],'EVALUACION DE RIESGO'!A:A,1,FALSE)=Tabla2[[#This Row],[ID]],"SI","NO"),"NO")
A251: 10-GCO | B251: PRODUCTIVO | C251: Gestión de Colocaciones | D251: GCO | E251: Gestión de PYMES | F251: - | G251: Destino y control a los créditos PYME | H251: Formulario de destino del crédito | I251: Formulario adjunto al file del crédito | J251: Gerente de Negocios | K251: FIT | L251: UBICACIÓN DIGITAL-CORE FINANCIERO | M251: DOCUMENTO DE ARCHIVO-ELECTRÓNICO | N251: PRIMARIOS | O251: INFORMACIÓN DE SOCIOS Y CLIENTES | P251: USO INTERNO(2) | Q251: MEDIA(2) | R251: MEDIA(2) | S251: =+(IF(P251="PUBLICA(1)",1,IF(P251="USO INTERNO(2)",2,IF(P251="RESTRINGIDO(3)",3,3))))+(IF(Q251="BAJA(1)",1,IF(Q251="MEDIA(2)",2,IF(Q251="ALTA(3)",3,3))))+(IF(R251="BAJA(1)",1,IF(R251="MEDIA(2)",2,IF(R251="ALTA(3)",3,3)))) | T251: =+IF(S251<6,"BAJA",IF(S251<8,"MEDIA","ALTA")) | U251: - | V251: 8/02/225 | W251: N/A | X251: =+IFERROR(IF(VLOOKUP(Tabla2[[#This Row],[ID]],'EVALUACION DE RIESGO'!A:A,1,FALSE)=Tabla2[[#This Row],[ID]],"SI","NO"),"NO")
A252: 11-GCO | B252: PRODUCTIVO | C252: Gestión de Colocaciones | D252: GCO | E252: Procesamiento de Crédito | F252: - | G252: Predespacho de solicitudes de crédito | H252: Registro del sistema | I252: Registro realizado en el sistema como una etapa de la revisión y aprobación del crédito | J252: Jefe de Negocios | K252: FIT | L252: UBICACIÓN DIGITAL-CORE FINANCIERO | M252: DOCUMENTO DE ARCHIVO-ELECTRÓNICO | N252: PRIMARIOS | O252: INFORMACIÓN DE SOCIOS Y CLIENTES | P252: USO INTERNO(2) | Q252: BAJA(1) | R252: MEDIA(2) | S252: =+(IF(P252="PUBLICA(1)",1,IF(P252="USO INTERNO(2)",2,IF(P252="RESTRINGIDO(3)",3,3))))+(IF(Q252="BAJA(1)",1,IF(Q252="MEDIA(2)",2,IF(Q252="ALTA(3)",3,3))))+(IF(R252="BAJA(1)",1,IF(R252="MEDIA(2)",2,IF(R252="ALTA(3)",3,3)))) | T252: =+IF(S252<6,"BAJA",IF(S252<8,"MEDIA","ALTA")) | U252: - | V252: 8/02/225 | W252: N/A | X252: =+IFERROR(IF(VLOOKUP(Tabla2[[#This Row],[ID]],'EVALUACION DE RIESGO'!A:A,1,FALSE)=Tabla2[[#This Row],[ID]],"SI","NO"),"NO")
A253: 12-GCO | B253: PRODUCTIVO | C253: Gestión de Colocaciones | D253: GCO | E253: Procesamiento de Crédito | F253: - | G253: Verificación de Información de la Solicitud de Crédito | H253: File de crédito | I253: File digital que contiene toda la documentación referente a los lineamientos del tipo de crédito | J253: Jefe de Negocios | K253: FIT | L253: UBICACIÓN DIGITAL-CORE FINANCIERO | M253: DOCUMENTO DE ARCHIVO-ELECTRÓNICO | N253: PRIMARIOS | O253: INFORMACIÓN DE SOCIOS Y CLIENTES | P253: RESTRINGIDO(3) | Q253: MEDIA(2) | R253: MEDIA(2) | S253: =+(IF(P253="PUBLICA(1)",1,IF(P253="USO INTERNO(2)",2,IF(P253="RESTRINGIDO(3)",3,3))))+(IF(Q253="BAJA(1)",1,IF(Q253="MEDIA(2)",2,IF(Q253="ALTA(3)",3,3))))+(IF(R253="BAJA(1)",1,IF(R253="MEDIA(2)",2,IF(R253="ALTA(3)",3,3)))) | T253: =+IF(S253<6,"BAJA",IF(S253<8,"MEDIA","ALTA")) | U253: - | V253: 8/02/225 | W253: N/A | X253: =+IFERROR(IF(VLOOKUP(Tabla2[[#This Row],[ID]],'EVALUACION DE RIESGO'!A:A,1,FALSE)=Tabla2[[#This Row],[ID]],"SI","NO"),"NO")
... A295: 54-GCO | B295: PRODUCTIVO | C295: Gestión de Colocaciones | D295: GCO | E295: Gestión de Compra y Venta de Cartera | F295: - | G295: Entrega de datos y cobro de la venta | H295: Reporte de Cartera Vendida | I295: Reporte procesado por Operaciones para el registro en el Core Financiero | J295: Gerente de Negocios | K295: Gerente de Negocios | L295: UBICACIÓN DIGITAL-EQUIPO DEL RESPONSABLE | M295: DISCOS DUROS, SERVIDORES, DISCOS O MEDIOS PORTÁTILES, CINTAS O MEDIOS DE VIDEO Y AUDIO, ETC. | N295: PRIMARIOS | O295: DOCUMENTOS TÉCNICOS | P295: RESTRINGIDO(3) | Q295: MEDIA(2) | R295: MEDIA(2) | S295: =+(IF(P295="PUBLICA(1)",1,IF(P295="USO INTERNO(2)",2,IF(P295="RESTRINGIDO(3)",3,3))))+(IF(Q295="BAJA(1)",1,IF(Q295="MEDIA(2)",2,IF(Q295="ALTA(3)",3,3))))+(IF(R295="BAJA(1)",1,IF(R295="MEDIA(2)",2,IF(R295="ALTA(3)",3,3)))) | T295: =+IF(S295<6,"BAJA",IF(S295<8,"MEDIA","ALTA")) | U295: - | V295: 8/02/225 | W295: N/A | X295: =+IFERROR(IF(VLOOKUP(Tabla2[[#This Row],[ID]],'EVALUACION DE RIESGO'!A:A,1,FALSE)=Tabla2[[#This Row],[ID]],"SI","NO"),"NO")
A296: 55-GCO | B296: PRODUCTIVO | C296: Gestión de Colocaciones | D296: GCO | E296: N/A | F296: - | G296: N/A | H296: Equipos de computación | I296: Equipos de computación donde se realiza la gestión del área | J296: Gerente de Negocios | K296: Gerente de Negocios | L296: UBICACIÓN FISICA-MATRIZ ATUNTAQUI | M296: DISCOS DUROS, SERVIDORES, DISCOS O MEDIOS PORTÁTILES, CINTAS O MEDIOS DE VIDEO Y AUDIO, ETC. | N296: APOYO | O296: HARDWARE | P296: RESTRINGIDO(3) | Q296: MEDIA(2) | R296: MEDIA(2) | S296: =+(IF(P296="PUBLICA(1)",1,IF(P296="USO INTERNO(2)",2,IF(P296="RESTRINGIDO(3)",3,3))))+(IF(Q296="BAJA(1)",1,IF(Q296="MEDIA(2)",2,IF(Q296="ALTA(3)",3,3))))+(IF(R296="BAJA(1)",1,IF(R296="MEDIA(2)",2,IF(R296="ALTA(3)",3,3)))) | T296: =+IF(S296<6,"BAJA",IF(S296<8,"MEDIA","ALTA")) | U296: - | V296: 45712 | W296: N/A | X296: =+IFERROR(IF(VLOOKUP(Tabla2[[#This Row],[ID]],'EVALUACION DE RIESGO'!A:A,1,FALSE)=Tabla2[[#This Row],[ID]],"SI","NO"),"NO")
A297: 56-GCO | B297: PRODUCTIVO | C297: Gestión de Colocaciones | D297: GCO | E297: N/A | F297: - | G297: N/A | H297: Gerente de Negocios | I297: N/A | J297: Gerente de Negocios | K297: N/A | L297: N/A | M297: N/A | N297: APOYO | O297: RECURSO HUMANO | P297: USO INTERNO(2) | Q297: MEDIA(2) | R297: MEDIA(2) | S297: =+(IF(P297="PUBLICA(1)",1,IF(P297="USO INTERNO(2)",2,IF(P297="RESTRINGIDO(3)",3,3))))+(IF(Q297="BAJA(1)",1,IF(Q297="MEDIA(2)",2,IF(Q297="ALTA(3)",3,3))))+(IF(R297="BAJA(1)",1,IF(R297="MEDIA(2)",2,IF(R297="ALTA(3)",3,3)))) | T297: =+IF(S297<6,"BAJA",IF(S297<8,"MEDIA","ALTA")) | U297: - | V297: 45712 | W297: N/A | X297: =+IFERROR(IF(VLOOKUP(Tabla2[[#This Row],[ID]],'EVALUACION DE RIESGO'!A:A,1,FALSE)=Tabla2[[#This Row],[ID]],"SI","NO"),"NO")
A298: 57-GCO | B298: PRODUCTIVO | C298: Gestión de Colocaciones | D298: GCO | E298: N/A | F298: - | G298: N/A | H298: Jefe de Negocios | I298: N/A | J298: Jefe de Negocios | K298: N/A | L298: N/A | M298: N/A | N298: APOYO | O298: RECURSO HUMANO | P298: USO INTERNO(2) | Q298: MEDIA(2) | R298: MEDIA(2) | S298: =+(IF(P298="PUBLICA(1)",1,IF(P298="USO INTERNO(2)",2,IF(P298="RESTRINGIDO(3)",3,3))))+(IF(Q298="BAJA(1)",1,IF(Q298="MEDIA(2)",2,IF(Q298="ALTA(3)",3,3))))+(IF(R298="BAJA(1)",1,IF(R298="MEDIA(2)",2,IF(R298="ALTA(3)",3,3)))) | T298: =+IF(S298<6,"BAJA",IF(S298<8,"MEDIA","ALTA")) | U298: - | V298: 45712 | W298: N/A | X298: =+IFERROR(IF(VLOOKUP(Tabla2[[#This Row],[ID]],'EVALUACION DE RIESGO'!A:A,1,FALSE)=Tabla2[[#This Row],[ID]],"SI","NO"),"NO")
A299: 1-GNE | B299: PRODUCTIVO | C299: Gestión de Negocios | D299: GNE | E299: Gestión de Marketing | F299: - | G299: Elaboración del Plan de Medios | H299: Plan de Medios | I299: Estrategia detallada que describe los canales y recursos utilizados para la difusión de las campañas de marketing. | J299: Jefe de Marketing | K299: Jefe de Marketing | L299: UBICACIÓN DIGITAL-EQUIPO DEL RESPONSABLE | M299: DISCOS DUROS, SERVIDORES, DISCOS O MEDIOS PORTÁTILES, CINTAS O MEDIOS DE VIDEO Y AUDIO, ETC. | N299: PRIMARIOS | O299: DOCUMENTOS TÉCNICOS | P299: USO INTERNO(2) | Q299: MEDIA(2) | R299: BAJA(1) | S299: =+(IF(P299="PUBLICA(1)",1,IF(P299="USO INTERNO(2)",2,IF(P299="RESTRINGIDO(3)",3,3))))+(IF(Q299="BAJA(1)",1,IF(Q299="MEDIA(2)",2,IF(Q299="ALTA(3)",3,3))))+(IF(R299="BAJA(1)",1,IF(R299="MEDIA(2)",2,IF(R299="ALTA(3)",3,3)))) | T299: =+IF(S299<6,"BAJA",IF(S299<8,"MEDIA","ALTA")) | U299: - | V299: 45580 | W299: N/A | X299: =+IFERROR(IF(VLOOKUP(Tabla2[[#This Row],[ID]],'EVALUACION DE RIESGO'!A:A,1,FALSE)=Tabla2[[#This Row],[ID]],"SI","NO"),"NO")
A300: 2-GNE | B300: PRODUCTIVO | C300: Gestión de Negocios | D300: GNE | E300: Gestión de Marketing | F300: - | G300: Elaboración del Plan de Marketing | H300: Plan de Marketing | I300: Documento integral que incluye las estrategias, objetivos y tácticas para promocionar los productos o servicios de la cooperativa. | J300: Jefe de Marketing | K300: Jefe de Marketing | L300: UBICACIÓN DIGITAL-EQUIPO DEL RESPONSABLE | M300: DISCOS DUROS, SERVIDORES, DISCOS O MEDIOS PORTÁTILES, CINTAS O MEDIOS DE VIDEO Y AUDIO, ETC. | N300: PRIMARIOS | O300: DOCUMENTOS TÉCNICOS | P300: USO INTERNO(2) | Q300: BAJA(1) | R300: MEDIA(2) | S300: =+(IF(P300="PUBLICA(1)",1,IF(P300="USO INTERNO(2)",2,IF(P300="RESTRINGIDO(3)",3,3))))+(IF(Q300="BAJA(1)",1,IF(Q300="MEDIA(2)",2,IF(Q300="ALTA(3)",3,3))))+(IF(R300="BAJA(1)",1,IF(R300="MEDIA(2)",2,IF(R300="ALTA(3)",3,3)))) | T300: =+IF(S300<6,"BAJA",IF(S300<8,"MEDIA","ALTA")) | U300: - | V300: 45580 | W300: N/A | X300: =+IFERROR(IF(VLOOKUP(Tabla2[[#This Row],[ID]],'EVALUACION DE RIESGO'!A:A,1,FALSE)=Tabla2[[#This Row],[ID]],"SI","NO"),"NO")
A301: 3-GNE | B301: PRODUCTIVO | C301: Gestión de Negocios | D301: GNE | E301: Gestión de Marketing | F301: - | G301: Diseño y ejecución de campañas publicitarias | H301: Brief (Síntesis) de la campaña publicitaria integral. | I301: Resumen conciso de la campaña publicitaria, incluyendo los objetivos, el público objetivo, los mensajes clave y los canales de comunicación. | J301: Jefe de Marketing | K301: Jefe de Marketing | L301: UBICACIÓN DIGITAL-EQUIPO DEL RESPONSABLE | M301: DISCOS DUROS, SERVIDORES, DISCOS O MEDIOS PORTÁTILES, CINTAS O MEDIOS DE VIDEO Y AUDIO, ETC. | N301: PRIMARIOS | O301: DOCUMENTOS TÉCNICOS | P301: USO INTERNO(2) | Q301: BAJA(1) | R301: BAJA(1) | S301: =+(IF(P301="PUBLICA(1)",1,IF(P301="USO INTERNO(2)",2,IF(P301="RESTRINGIDO(3)",3,3))))+(IF(Q301="BAJA(1)",1,IF(Q301="MEDIA(2)",2,IF(Q301="ALTA(3)",3,3))))+(IF(R301="BAJA(1)",1,IF(R301="MEDIA(2)",2,IF(R301="ALTA(3)",3,3)))) | T301: =+IF(S301<6,"BAJA",IF(S301<8,"MEDIA","ALTA")) | U301: - | V301: 45580 | W301: N/A | X301: =+IFERROR(IF(VLOOKUP(Tabla2[[#This Row],[ID]],'EVALUACION DE RIESGO'!A:A,1,FALSE)=Tabla2[[#This Row],[ID]],"SI","NO"),"NO")
A302: 4-GNE | B302: PRODUCTIVO | C302: Gestión de Negocios | D302: GNE | E302: Gestión de Marketing | F302: - | G302: Diseño y ejecución de campañas publicitarias | H302: Campaña publicitaria integral o específica | I302: Actividad promocional que puede ser general (integral) o centrada en un producto o servicio específico, con estrategias y tácticas detalladas. | J302: Jefe de Marketing | K302: Jefe de Marketing | L302: UBICACIÓN DIGITAL-EQUIPO DEL RESPONSABLE | M302: DISCOS DUROS, SERVIDORES, DISCOS O MEDIOS PORTÁTILES, CINTAS O MEDIOS DE VIDEO Y AUDIO, ETC. | N302: PRIMARIOS | O302: DOCUMENTOS TÉCNICOS | P302: USO INTERNO(2) | Q302: BAJA(1) | R302: BAJA(1) | S302: =+(IF(P302="PUBLICA(1)",1,IF(P302="USO INTERNO(2)",2,IF(P302="RESTRINGIDO(3)",3,3))))+(IF(Q302="BAJA(1)",1,IF(Q302="MEDIA(2)",2,IF(Q302="ALTA(3)",3,3))))+(IF(R302="BAJA(1)",1,IF(R302="MEDIA(2)",2,IF(R302="ALTA(3)",3,3)))) | T302: =+IF(S302<6,"BAJA",IF(S302<8,"MEDIA","ALTA")) | U302: - | V302: 45580 | W302: N/A | X302: =+IFERROR(IF(VLOOKUP(Tabla2[[#This Row],[ID]],'EVALUACION DE RIESGO'!A:A,1,FALSE)=Tabla2[[#This Row],[ID]],"SI","NO"),"NO")
A303: 5-GNE | B303: PRODUCTIVO | C303: Gestión de Negocios | D303: GNE | E303: Gestión de Marketing | F303: - | G303: Diseño y ejecución de campañas publicitarias | H303: Certificaciones de Pautaje. | I303: Documentos que certifican el tiempo, el espacio o los medios utilizados para la difusión de una campaña publicitaria. | J303: Jefe de Marketing | K303: Jefe de Marketing | L303: UBICACIÓN DIGITAL-EQUIPO DEL RESPONSABLE | M303: DISCOS DUROS, SERVIDORES, DISCOS O MEDIOS PORTÁTILES, CINTAS O MEDIOS DE VIDEO Y AUDIO, ETC. | N303: PRIMARIOS | O303: DOCUMENTOS TÉCNICOS | P303: USO INTERNO(2) | Q303: MEDIA(2) | R303: BAJA(1) | S303: =+(IF(P303="PUBLICA(1)",1,IF(P303="USO INTERNO(2)",2,IF(P303="RESTRINGIDO(3)",3,3))))+(IF(Q303="BAJA(1)",1,IF(Q303="MEDIA(2)",2,IF(Q303="ALTA(3)",3,3))))+(IF(R303="BAJA(1)",1,IF(R303="MEDIA(2)",2,IF(R303="ALTA(3)",3,3)))) | T303: =+IF(S303<6,"BAJA",IF(S303<8,"MEDIA","ALTA")) | U303: - | V303: 45580 | W303: N/A | X303: =+IFERROR(IF(VLOOKUP(Tabla2[[#This Row],[ID]],'EVALUACION DE RIESGO'!A:A,1,FALSE)=Tabla2[[#This Row],[ID]],"SI","NO"),"NO")
A304: 6-GNE | B304: PRODUCTIVO | C304: Gestión de Negocios | D304: GNE | E304: Gestión de Marketing | F304: - | G304: Diseño y ejecución de campañas publicitarias | H304: Análisis de resultados de campañas publicitarias. | I304: Evaluación del impacto y el rendimiento de las campañas de marketing y publicidad, con indicadores clave de rendimiento (KPI). | J304: Jefe de Marketing | K304: Jefe de Marketing | L304: UBICACIÓN DIGITAL-EQUIPO DEL RESPONSABLE | M304: DISCOS DUROS, SERVIDORES, DISCOS O MEDIOS PORTÁTILES, CINTAS O MEDIOS DE VIDEO Y AUDIO, ETC. | N304: PRIMARIOS | O304: DOCUMENTOS TÉCNICOS | P304: USO INTERNO(2) | Q304: MEDIA(2) | R304: MEDIA(2) | S304: =+(IF(P304="PUBLICA(1)",1,IF(P304="USO INTERNO(2)",2,IF(P304="RESTRINGIDO(3)",3,3))))+(IF(Q304="BAJA(1)",1,IF(Q304="MEDIA(2)",2,IF(Q304="ALTA(3)",3,3))))+(IF(R304="BAJA(1)",1,IF(R304="MEDIA(2)",2,IF(R304="ALTA(3)",3,3)))) | T304: =+IF(S304<6,"BAJA",IF(S304<8,"MEDIA","ALTA")) | U304: - | V304: 45580 | W304: N/A | X304: =+IFERROR(IF(VLOOKUP(Tabla2[[#This Row],[ID]],'EVALUACION DE RIESGO'!A:A,1,FALSE)=Tabla2[[#This Row],[ID]],"SI","NO"),"NO")
A305: 7-GNE | B305: PRODUCTIVO | C305: Gestión de Negocios | D305: GNE | E305: Gestión de Marketing | F305: - | G305: Diseño y ejecución de campañas publicitarias | H305: Matriz de revisión de la publicidad. | I305: Herramienta que permite hacer un seguimiento y revisión de los distintos elementos de la campaña publicitaria, para asegurar la alineación con los objetivos. | J305: Jefe de Marketing | K305: Jefe de Marketing | L305: UBICACIÓN DIGITAL-EQUIPO DEL RESPONSABLE | M305: DISCOS DUROS, SERVIDORES, DISCOS O MEDIOS PORTÁTILES, CINTAS O MEDIOS DE VIDEO Y AUDIO, ETC. | N305: PRIMARIOS | O305: DOCUMENTOS TÉCNICOS | P305: USO INTERNO(2) | Q305: BAJA(1) | R305: BAJA(1) | S305: =+(IF(P305="PUBLICA(1)",1,IF(P305="USO INTERNO(2)",2,IF(P305="RESTRINGIDO(3)",3,3))))+(IF(Q305="BAJA(1)",1,IF(Q305="MEDIA(2)",2,IF(Q305="ALTA(3)",3,3))))+(IF(R305="BAJA(1)",1,IF(R305="MEDIA(2)",2,IF(R305="ALTA(3)",3,3)))) | T305: =+IF(S305<6,"BAJA",IF(S305<8,"MEDIA","ALTA")) | U305: - | V305: 45580 | W305: N/A | X305: =+IFERROR(IF(VLOOKUP(Tabla2[[#This Row],[ID]],'EVALUACION DE RIESGO'!A:A,1,FALSE)=Tabla2[[#This Row],[ID]],"SI","NO"),"NO")
A306: 8-GNE | B306: PRODUCTIVO | C306: Gestión de Negocios | D306: GNE | E306: Gestión de Marketing | F306: - | G306: Diseño y elaboración de promocionales y merchandising | H306: Acta entrega de material promocional a oficinas. | I306: documento que certifica la entrega formal del material de marketing a las oficinas para su distribución. | J306: Jefe de Marketing | K306: Jefe de Marketing | L306: UBICACIÓN DIGITAL-EQUIPO DEL RESPONSABLE | M306: DISCOS DUROS, SERVIDORES, DISCOS O MEDIOS PORTÁTILES, CINTAS O MEDIOS DE VIDEO Y AUDIO, ETC. | N306: PRIMARIOS | O306: DOCUMENTOS TÉCNICOS | P306: USO INTERNO(2) | Q306: MEDIA(2) | R306: MEDIA(2) | S306: =+(IF(P306="PUBLICA(1)",1,IF(P306="USO INTERNO(2)",2,IF(P306="RESTRINGIDO(3)",3,3))))+(IF(Q306="BAJA(1)",1,IF(Q306="MEDIA(2)",2,IF(Q306="ALTA(3)",3,3))))+(IF(R306="BAJA(1)",1,IF(R306="MEDIA(2)",2,IF(R306="ALTA(3)",3,3)))) | T306: =+IF(S306<6,"BAJA",IF(S306<8,"MEDIA","ALTA")) | U306: - | V306: 45580 | W306: N/A | X306: =+IFERROR(IF(VLOOKUP(Tabla2[[#This Row],[ID]],'EVALUACION DE RIESGO'!A:A,1,FALSE)=Tabla2[[#This Row],[ID]],"SI","NO"),"NO")
A307: 9-GNE | B307: PRODUCTIVO | C307: Gestión de Negocios | D307: GNE | E307: Gestión de Marketing | F307: - | G307: Diseño y elaboración de promocionales y merchandising | H307: Registro de entrega de promocionales. | I307: Base de datos o listado que lleva el control de la entrega de materiales promocionales, como folletos, flyers y otros productos. | J307: Jefe de Marketing | K307: Jefe de Marketing | L307: UBICACIÓN DIGITAL-EQUIPO DEL RESPONSABLE | M307: DISCOS DUROS, SERVIDORES, DISCOS O MEDIOS PORTÁTILES, CINTAS O MEDIOS DE VIDEO Y AUDIO, ETC. | N307: PRIMARIOS | O307: DOCUMENTOS TÉCNICOS | P307: USO INTERNO(2) | Q307: MEDIA(2) | R307: MEDIA(2) | S307: =+(IF(P307="PUBLICA(1)",1,IF(P307="USO INTERNO(2)",2,IF(P307="RESTRINGIDO(3)",3,3))))+(IF(Q307="BAJA(1)",1,IF(Q307="MEDIA(2)",2,IF(Q307="ALTA(3)",3,3))))+(IF(R307="BAJA(1)",1,IF(R307="MEDIA(2)",2,IF(R307="ALTA(3)",3,3)))) | T307: =+IF(S307<6,"BAJA",IF(S307<8,"MEDIA","ALTA")) | U307: - | V307: 45580 | W307: N/A | X307: =+IFERROR(IF(VLOOKUP(Tabla2[[#This Row],[ID]],'EVALUACION DE RIESGO'!A:A,1,FALSE)=Tabla2[[#This Row],[ID]],"SI","NO"),"NO")
...

Sheet INTERVALOS
A1: PROBABILIDAD
A2: Descripción | B2: Nivel | C2: Porcentaje de ocurrencia del evento | D2: Frecuencia
A3: Muy Baja | B3: 1 | C3: 0,00% al 4,64% | D3: Ocurre una vez al año
A4: Baja | B4: 2 | C4: 4,65% al 7,60% | D4: Ocurre una vez al mes
A5: Media | B5: 3 | C5: 7.61% al 28,26% | D5: Ocurre una vez a la semana
A6: Alta | B6: 4 | C6: 28,27% al 40,70% | D6: Ocurre una vez al día
A7: Muy Alta | B7: 5 | C7: 40,71% al 100% | D7: Ocurre varias veces al día.
A9: IMPACTO/DEGRADACIÓN
A10: Descripcion | B10: Nivel
A11: Insignificante | B11: 1
A12: Bajo | B12: 2
A13: Medio | B13: 3
A14: Alto | B14: 4
A15: Severo | B15: 5
A17: NIVEL DE RIESGO DE SEGURIDAD = IMPACTO * PROBABILIDAD
A18: PROBABILIDAD | B18: IMPACTO
B19: Insignificante | C19: Bajo | D19: Medio | E19: Alto | F19: Severo | H19: NIVEL DE RIESGO
A20: Muy Alta | B20: 5 | C20: 10 | D20: 15 | E20: 20 | F20: 25 | H20: Crítico | I20: 17-25
A21: Alta | B21: 4 | C21: 8 | D21: 12 | E21: 16 | F21: 20 | H21: Alto | I21: 10-16
A22: Media | B22: 3 | C22: 6 | D22: 9 | E22: 12 | F22: 15 | H22: Medio | I22: 5-9
A23: Baja | B23: 2 | C23: 4 | D23: 6 | E23: 8 | F23: 10 | H23: Bajo | I23: 1-4
A24: Muy Baja | B24: 1 | C24: 2 | D24: 3 | E24: 4 | F24: 5

Sheet EVALUACION DE RIESGO
A2: ACTIVO | B2: NOMBRE | C2: DESCRIPCION | D2: TIPO DE ACTIVO MAGGERIT | E2: EVENTO DE AMENAZA | F2: CID | G2: CONFIDENCIALIDAD | H2: INTEGRIDAD | I2: DISPONIBILIDAD | J2: PROBABILIDAD | K2: IMPACTO | L2: RIESGO INHERENTE | M2: DETERMINACION RIESGO ACUMULADO O INHERENTE | N2: CONTROLES EXISTENTES | O2: TIPO DE PROTECCION | P2: MADUREZ DEL CONTROL | Q2: VALOR DE EFICACIA | R2: VULNERABILIDADES | S2: PROBABILIDAD RESIDUAL | T2: IMPACTO RESIDUAL | U2: RIESGO RESIDUAL | V2: DETERMINACION RIESGO RESIDUAL | W2: APETITO DE RIESGO | X2: REQUIERE TRATAMIENTO NORMATIVA SEPS 002-2022 | Y2: PLAN DE ACCION | Z2: DESCIPCION PLAN DE ACCIÓN
A3: 16-GTI | B3: Respaldo de información | C3: Respaldo de Base de Datos (diario) | D3: [Media] Soportes de información | E3: [E.2] Errores del administrador | F3: =+VLOOKUP(E3,'CATALOGO AMENAZA'!$B$2:$D$46,3,FALSE) | G3: X | H3: X | I3: X | J3: 2 | K3: 4 | L3: =+J3*K3 | M3: =+IF(L3<5,"BAJO",IF(L3<10,"MEDIO",IF(L3<17,"ALTO","CRITICO"))) | N3: Procedimientos operativos documentados | O3: PREVENTIVO | P3: Control Implementado sin evidencia de efectividad (Inefectivo prueba) | Q3: 0.3 | R3: Dependencia del administrador (error humano) | S3: =+IF(O3="PREVENTIVO",J3*(1-Q3),IF(O3="ADMINISTRACION",J3*(1-Q3),IF(O3="ELIMINACION",J3*(1-Q3),J3))) | T3: =+IF(O3="DETECTIVO",K3*(1-Q3),IF(O3="RECUPERACION",K3*(1-Q3),K3)) | U3: =+S3*T3 | V3: =+IF(U3<5,"BAJO",IF(U3<10,"MEDIO",IF(U3<17,"ALTO","CRITICO"))) | W3: MITIGAR | X3: - | Y3: - | Z3: -
A4: 16-GTI | B4: Respaldo de información | C4: Respaldo de Base de Datos (diario) | D4: [Media] Soportes de información | E4: [E.18] Destrucción de información | F4: =+VLOOKUP(E4,'CATALOGO AMENAZA'!$B$2:$D$46,3,FALSE) | I4: X | J4: 2 | K4: 4 | L4: =+J4*K4 | M4: =+IF(L4<5,"BAJO",IF(L4<10,"MEDIO",IF(L4<17,"ALTO","CRITICO"))) | N4: Respaldo digital de información | O4: PREVENTIVO | P4: Control Implementado sin evidencia de efectividad (Inefectivo prueba) | Q4: 0.3 | R4: Almacenamiento manual en medio extraible | S4: =+IF(O4="PREVENTIVO",J4*(1-Q4),IF(O4="ADMINISTRACION",J4*(1-Q4),IF(O4="ELIMINACION",J4*(1-Q4),J4))) | T4: =+IF(O4="DETECTIVO",K4*(1-Q4),IF(O4="RECUPERACION",K4*(1-Q4),K4)) | U4: =+S4*T4 | V4: =+IF(U4<5,"BAJO",IF(U4<10,"MEDIO",IF(U4<17,"ALTO","CRITICO"))) | W4: MITIGAR | X4: - | Y4: - | Z4: -
A5: 16-GTI | B5: Respaldo de información | C5: Respaldo de Base de Datos (diario) | D5: [Media] Soportes de información | E5: [N.1] Fuego | F5: =+VLOOKUP(E5,'CATALOGO AMENAZA'!$B$2:$D$46,3,FALSE) | I5: X | J5: 1 | K5: 4 | L5: =+J5*K5 | M5: =+IF(L5<5,"BAJO",IF(L5<10,"MEDIO",IF(L5<17,"ALTO","CRITICO"))) | N5: Sistema contra incendios | O5: PREVENTIVO | P5: Control Implementado sin evidencia de efectividad (Inefectivo prueba) | Q5: 0.3 | R5: - | S5: =+IF(O5="PREVENTIVO",J5*(1-Q5),IF(O5="ADMINISTRACION",J5*(1-Q5),IF(O5="ELIMINACION",J5*(1-Q5),J5))) | T5: =+IF(O5="DETECTIVO",K5*(1-Q5),IF(O5="RECUPERACION",K5*(1-Q5),K5)) | U5: =+S5*T5 | V5: =+IF(U5<5,"BAJO",IF(U5<10,"MEDIO",IF(U5<17,"ALTO","CRITICO"))) | W5: ACEPTABLE | X5: - | Y5: - | Z5: -
A6: 16-GTI | B6: Respaldo de información | C6: Respaldo de Base de Datos (diario) | D6: [Media] Soportes de información | E6: [E.19] Fugas de información | F6: =+VLOOKUP(E6,'CATALOGO AMENAZA'!$B$2:$D$46,3,FALSE) | G6: X | J6: 2 | K6: 4 | L6: =+J6*K6 | M6: =+IF(L6<5,"BAJO",IF(L6<10,"MEDIO",IF(L6<17,"ALTO","CRITICO"))) | N6: Politicas de manejo de información | O6: PREVENTIVO | P6: Control Implementado sin evidencia de efectividad (Inefectivo prueba) | Q6: 0.3 | R6: Dispositivos no encriptados | S6: =+IF(O6="PREVENTIVO",J6*(1-Q6),IF(O6="ADMINISTRACION",J6*(1-Q6),IF(O6="ELIMINACION",J6*(1-Q6),J6))) | T6: =+IF(O6="DETECTIVO",K6*(1-Q6),IF(O6="RECUPERACION",K6*(1-Q6),K6)) | U6: =+S6*T6 | V6: =+IF(U6<5,"BAJO",IF(U6<10,"MEDIO",IF(U6<17,"ALTO","CRITICO"))) | W6: MITIGAR | X6: - | Y6: - | Z6: -
A7: 21-GTI | B7: Registro control de respaldos | C7: Matriz de registro de respaldos realizados por fechas, tipo de respaldo y responsable | D7: [D] Datos / Información / datos de configuración | E7: [E.2] Errores del administrador | F7: =+VLOOKUP(E7,'CATALOGO AMENAZA'!$B$2:$D$46,3,FALSE) | G7: X | H7: X | I7: X | J7: 1 | K7: 2 | L7: =+J7*K7 | M7: =+IF(L7<5,"BAJO",IF(L7<10,"MEDIO",IF(L7<17,"ALTO","CRITICO"))) | N7: Procedimientos operativos documentados | O7: PREVENTIVO | P7: Control Implementado sin evidencia de efectividad (Inefectivo prueba) | Q7: 0.3 | R7: Dependencia del administrador (error humano) | S7: =+IF(O7="PREVENTIVO",J7*(1-Q7),IF(O7="ADMINISTRACION",J7*(1-Q7),IF(O7="ELIMINACION",J7*(1-Q7),J7))) | T7: =+IF(O7="DETECTIVO",K7*(1-Q7),IF(O7="RECUPERACION",K7*(1-Q7),K7)) | U7: =+S7*T7 | V7: =+IF(U7<5,"BAJO",IF(U7<10,"MEDIO",IF(U7<17,"ALTO","CRITICO"))) | W7: ACEPTABLE | X7: - | Y7: - | Z7: -
A8: 63-GTI | B8: Home Banking | C8: Aplicación Banca Virtual | D8: [SW] Software - Aplicaciones informáticas | E8: [A.11] Acceso no autorizado | F8: =+VLOOKUP(E8,'CATALOGO AMENAZA'!$B$2:$D$46,3,FALSE) | G8: X | H8: X | J8: 4 | K8: 5 | L8: =+J8*K8 | M8: =+IF(L8<5,"BAJO",IF(L8<10,"MEDIO",IF(L8<17,"ALTO","CRITICO"))) | N8: Control de accesos | O8: PREVENTIVO | P8: Control Implementado sin evidencia de efectividad (Inefectivo prueba) | Q8: 0.3 | R8: Usuarios sin monitoreo | S8: =+IF(O8="PREVENTIVO",J8*(1-Q8),IF(O8="ADMINISTRACION",J8*(1-Q8),IF(O8="ELIMINACION",J8*(1-Q8),J8))) | T8: =+IF(O8="DETECTIVO",K8*(1-Q8),IF(O8="RECUPERACION",K8*(1-Q8),K8)) | U8: =+S8*T8 | V8: =+IF(U8<5,"BAJO",IF(U8<10,"MEDIO",IF(U8<17,"ALTO","CRITICO"))) | W8: MITIGAR | X8: REQUIERE TRATAMIENTO | Y8: PA-SI-001 | Z8: Identificar herramientas que permitan realizar un análisis de LOGS
A9: 63-GTI | B9: Home Banking | C9: Aplicación Banca Virtual | D9: [SW] Software - Aplicaciones informáticas | E9: [A.5] Suplantación de la identidad del usuario | F9: =+VLOOKUP(E9,'CATALOGO AMENAZA'!$B$2:$D$46,3,FALSE) | G9: X | H9: X | J9: 4 | K9: 5 | L9: =+J9*K9 | M9: =+IF(L9<5,"BAJO",IF(L9<10,"MEDIO",IF(L9<17,"ALTO","CRITICO"))) | N9: Doble autenticación | O9: ELIMINACION | P9: Control Implementado sin evidencia de efectividad (Inefectivo prueba) | Q9: 0.8 | R9: - | S9: =+IF(O9="PREVENTIVO",J9*(1-Q9),IF(O9="ADMINISTRACION",J9*(1-Q9),IF(O9="ELIMINACION",J9*(1-Q9),J9))) | T9: =+IF(O9="DETECTIVO",K9*(1-Q9),IF(O9="RECUPERACION",K9*(1-Q9),K9)) | U9: =+S9*T9 | V9: =+IF(U9<5,"BAJO",IF(U9<10,"MEDIO",IF(U9<17,"ALTO","CRITICO"))) | W9: ACEPTABLE | X9: - | Y9: - | Z9: -
A10: 63-GTI | B10: Home Banking | C10: Aplicación Banca Virtual | D10: [SW] Software - Aplicaciones informáticas | E10: [A.6] Abuso de privilegios de acceso | F10: =+VLOOKUP(E10,'CATALOGO AMENAZA'!$B$2:$D$46,3,FALSE) | G10: X | H10: X | I10: X | J10: 2 | K10: 4 | L10: =+J10*K10 | M10: =+IF(L10<5,"BAJO",IF(L10<10,"MEDIO",IF(L10<17,"ALTO","CRITICO"))) | N10: Registro de logs | O10: DETECTIVO | P10: Control Implementado sin evidencia de efectividad (Inefectivo prueba) | Q10: 0.3 | R10: Falta de revisión de perfiles de acceso | S10: =+IF(O10="PREVENTIVO",J10*(1-Q10),IF(O10="ADMINISTRACION",J10*(1-Q10),IF(O10="ELIMINACION",J10*(1-Q10),J10))) | T10: =+IF(O10="DETECTIVO",K10*(1-Q10),IF(O10="RECUPERACION",K10*(1-Q10),K10)) | U10: =+S10*T10 | V10: =+IF(U10<5,"BAJO",IF(U10<10,"MEDIO",IF(U10<17,"ALTO","CRITICO"))) | W10: MITIGAR | X10: - | Y10: - | Z10: -
A11: 63-GTI | B11: Home Banking | C11: Aplicación Banca Virtual | D11: [SW] Software - Aplicaciones informáticas | E11: [E.20] Vulnerabilidades de los programas (software) | F11: =+VLOOKUP(E11,'CATALOGO AMENAZA'!$B$2:$D$46,3,FALSE) | G11: X | H11: X | I11: X | J11: 4 | K11: 4 | L11: =+J11*K11 | M11: =+IF(L11<5,"BAJO",IF(L11<10,"MEDIO",IF(L11<17,"ALTO","CRITICO"))) | N11: Gestión de vulnerabilidades | O11: PREVENTIVO | P11: Control Implementado sin evidencia de efectividad (Inefectivo prueba) | Q11: 0.4 | R11: Recursos tecnológicos insuficientes para remediación | S11: =+IF(O11="PREVENTIVO",J11*(1-Q11),IF(O11="ADMINISTRACION",J11*(1-Q11),IF(O11="ELIMINACION",J11*(1-Q11),J11))) | T11: =+IF(O11="DETECTIVO",K11*(1-Q11),IF(O11="RECUPERACION",K11*(1-Q11),K11)) | U11: =+S11*T11 | V11: =+IF(U11<5,"BAJO",IF(U11<10,"MEDIO",IF(U11<17,"ALTO","CRITICO"))) | W11: MITIGAR | X11: - | Y11: - | Z11: -
A12: 63-GTI | B12: Home Banking | C12: Aplicación Banca Virtual | D12: [SW] Software - Aplicaciones informáticas | E12: [E.21] Errores de mantenimiento / actualización de programas (software) | F12: =+VLOOKUP(E12,'CATALOGO AMENAZA'!$B$2:$D$46,3,FALSE) | H12: X | I12: X | J12: 3 | K12: 4 | L12: =+J12*K12 | M12: =+IF(L12<5,"BAJO",IF(L12<10,"MEDIO",IF(L12<17,"ALTO","CRITICO"))) | N12: Gestión de vulnerabilidades | O12: PREVENTIVO | P12: Control Implementado sin evidencia de efectividad (Inefectivo prueba) | Q12: 0.4 | R12: Recursos tecnológicos insuficientes para remediación | S12: =+IF(O12="PREVENTIVO",J12*(1-Q12),IF(O12="ADMINISTRACION",J12*(1-Q12),IF(O12="ELIMINACION",J12*(1-Q12),J12))) | T12: =+IF(O12="DETECTIVO",K12*(1-Q12),IF(O12="RECUPERACION",K12*(1-Q12),K12)) | U12: =+S12*T12 | V12: =+IF(U12<5,"BAJO",IF(U12<10,"MEDIO",IF(U12<17,"ALTO","CRITICO"))) | W12: MITIGAR | X12: - | Y12: - | Z12: -
A13: 64-GTI | B13: Cooperativa Virtual | C13: Servidor que aloja la Banca Electronica 192.168.23.11 | D13: [HW] Equipamiento informático (hardware) | E13: [E.2] Errores del administrador | F13: =+VLOOKUP(E13,'CATALOGO AMENAZA'!$B$2:$D$46,3,FALSE) | G13: X | H13: X | I13: X | J13: 2 | K13: 4 | L13: =+J13*K13 | M13: =+IF(L13<5,"BAJO",IF(L13<10,"MEDIO",IF(L13<17,"ALTO","CRITICO"))) | N13: Control de cambios en los sistemas Verificación posterior (informe) | O13: ADMINISTRACION | P13: Control Implementado sin evidencia de efectividad (Inefectivo prueba) | Q13: 0.3 | R13: No existe procedimiento formal de gestión de cambios | S13: =+IF(O13="PREVENTIVO",J13*(1-Q13),IF(O13="ADMINISTRACION",J13*(1-Q13),IF(O13="ELIMINACION",J13*(1-Q13),J13))) | T13: =+IF(O13="DETECTIVO",K13*(1-Q13),IF(O13="RECUPERACION",K13*(1-Q13),K13)) | U13: =+S13*T13 | V13: =+IF(U13<5,"BAJO",IF(U13<10,"MEDIO",IF(U13<17,"ALTO","CRITICO"))) | W13: MITIGAR | X13: - | Y13: - | Z13: -
A14: 64-GTI | B14: Cooperativa Virtual | C14: Servidor que aloja la Banca Electronica 192.168.23.11 | D14: [HW] Equipamiento informático (hardware) | E14: [E.24] Caída del sistema por agotamiento de recursos | F14: =+VLOOKUP(E14,'CATALOGO AMENAZA'!$B$2:$D$46,3,FALSE) | I14: X | J14: 4 | K14: 4 | L14: =+J14*K14 | M14: =+IF(L14<5,"BAJO",IF(L14<10,"MEDIO",IF(L14<17,"ALTO","CRITICO"))) | N14: Monitoreo de Servidores presenta en el procedimiento operativo Administración de Servidores en el Manua de Gestión de las Operaciones de TI | O14: PREVENTIVO | P14: Control Implementado sin evidencia de efectividad (Inefectivo prueba) | Q14: 0.4 | R14: Falta de alertas automáticas | S14: =+IF(O14="PREVENTIVO",J14*(1-Q14),IF(O14="ADMINISTRACION",J14*(1-Q14),IF(O14="ELIMINACION",J14*(1-Q14),J14))) | T14: =+IF(O14="DETECTIVO",K14*(1-Q14),IF(O14="RECUPERACION",K14*(1-Q14),K14)) | U14: =+S14*T14 | V14: =+IF(U14<5,"BAJO",IF(U14<10,"MEDIO",IF(U14<17,"ALTO","CRITICO"))) | W14: MITIGAR | X14: - | Y14: - | Z14: -
A15: 64-GTI | B15: Cooperativa Virtual | C15: Servidor que aloja la Banca Electronica 192.168.23.11 | D15: [HW] Equipamiento informático (hardware) | E15: [A.11] Acceso no autorizado | F15: =+VLOOKUP(E15,'CATALOGO AMENAZA'!$B$2:$D$46,3,FALSE) | G15: X | H15: X | J15: 3 | K15: 4 | L15: =+J15*K15 | M15: =+IF(L15<5,"BAJO",IF(L15<10,"MEDIO",IF(L15<17,"ALTO","CRITICO"))) | N15: Control de accesos / VPN | O15: PREVENTIVO | P15: Control Implementado sin evidencia de efectividad (Inefectivo prueba) | Q15: 0.3 | R15: Contreaseñas de VPN no expiran | S15: =+IF(O15="PREVENTIVO",J15*(1-Q15),IF(O15="ADMINISTRACION",J15*(1-Q15),IF(O15="ELIMINACION",J15*(1-Q15),J15))) | T15: =+IF(O15="DETECTIVO",K15*(1-Q15),IF(O15="RECUPERACION",K15*(1-Q15),K15)) | U15: =+S15*T15 | V15: =+IF(U15<5,"BAJO",IF(U15<10,"MEDIO",IF(U15<17,"ALTO","CRITICO"))) | W15: MITIGAR | X15: - | Y15: - | Z15: -
A16: 64-GTI | B16: Cooperativa Virtual | C16: Servidor que aloja la Banca Electronica 192.168.23.11 | D16: [HW] Equipamiento informático (hardware) | E16: [A.23] Manipulación de los equipos | F16: =+VLOOKUP(E16,'CATALOGO AMENAZA'!$B$2:$D$46,3,FALSE) | G16: X | I16: X | J16: 3 | K16: 4 | L16: =+J16*K16 | M16: =+IF(L16<5,"BAJO",IF(L16<10,"MEDIO",IF(L16<17,"ALTO","CRITICO"))) | N16: Control de accesos | O16: PREVENTIVO | P16: Control Implementado sin evidencia de efectividad (Inefectivo prueba) | Q16: 0.3 | R16: Usuarios genéricos | S16: =+IF(O16="PREVENTIVO",J16*(1-Q16),IF(O16="ADMINISTRACION",J16*(1-Q16),IF(O16="ELIMINACION",J16*(1-Q16),J16))) | T16: =+IF(O16="DETECTIVO",K16*(1-Q16),IF(O16="RECUPERACION",K16*(1-Q16),K16)) | U16: =+S16*T16 | V16: =+IF(U16<5,"BAJO",IF(U16<10,"MEDIO",IF(U16<17,"ALTO","CRITICO"))) | W16: MITIGAR | X16: - | Y16: - | Z16: -
A17: 64-GTI | B17: Cooperativa Virtual | C17: Servidor que aloja la Banca Electronica 192.168.23.11 | D17: [HW] Equipamiento informático (hardware) | E17: [A.24] Denegación de servicio | F17: =+VLOOKUP(E17,'CATALOGO AMENAZA'!$B$2:$D$46,3,FALSE) | I17: X | J17: 4 | K17: 5 | L17: =+J17*K17 | M17: =+IF(L17<5,"BAJO",IF(L17<10,"MEDIO",IF(L17<17,"ALTO","CRITICO"))) | N17: Configuración segura de firewall | O17: PREVENTIVO | P17: Control Implementado sin evidencia de efectividad (Inefectivo prueba) | Q17: 0.3 | R17: Evidencia de validación de las configuraciones | S17: =+IF(O17="PREVENTIVO",J17*(1-Q17),IF(O17="ADMINISTRACION",J17*(1-Q17),IF(O17="ELIMINACION",J17*(1-Q17),J17))) | T17: =+IF(O17="DETECTIVO",K17*(1-Q17),IF(O17="RECUPERACION",K17*(1-Q17),K17)) | U17: =+S17*T17 | V17: =+IF(U17<5,"BAJO",IF(U17<10,"MEDIO",IF(U17<17,"ALTO","CRITICO"))) | W17: MITIGAR | X17: REQUIERE TRATAMIENTO | Y17: PA-SI-002 | Z17: Fortalecer mecanismos de protección contra ataques DoS/DDoS
A18: 64-GTI | B18: Cooperativa Virtual | C18: Servidor que aloja la Banca Electronica 192.168.23.11 | D18: [HW] Equipamiento informático (hardware) | E18: [E.23] Errores de mantenimiento / actualización de equipos (hardware) | F18: =+VLOOKUP(E18,'CATALOGO AMENAZA'!$B$2:$D$46,3,FALSE) | I18: X | J18: 3 | K18: 4 | L18: =+J18*K18 | M18: =+IF(L18<5,"BAJO",IF(L18<10,"MEDIO",IF(L18<17,"ALTO","CRITICO"))) | N18: Gestión de vulnerabilidades | O18: PREVENTIVO | P18: Control Implementado sin evidencia de efectividad (Inefectivo prueba) | Q18: 0.4 | R18: Recursos tecnológicos insuficientes para remediación | S18: =+IF(O18="PREVENTIVO",J18*(1-Q18),IF(O18="ADMINISTRACION",J18*(1-Q18),IF(O18="ELIMINACION",J18*(1-Q18),J18))) | T18: =+IF(O18="DETECTIVO",K18*(1-Q18),IF(O18="RECUPERACION",K18*(1-Q18),K18)) | U18: =+S18*T18 | V18: =+IF(U18<5,"BAJO",IF(U18<10,"MEDIO",IF(U18<17,"ALTO","CRITICO"))) | W18: MITIGAR | X18: - | Y18: - | Z18: -
A19: 65-GTI | B19: Sendmail | C19: Administracion Contenidos y Correo electrónico | D19: [S] Servicios | E19: [A.11] Acceso no autorizado | F19: =+VLOOKUP(E19,'CATALOGO AMENAZA'!$B$2:$D$46,3,FALSE) | G19: X | H19: X | J19: 2 | K19: 3 | L19: =+J19*K19 | M19: =+IF(L19<5,"BAJO",IF(L19<10,"MEDIO",IF(L19<17,"ALTO","CRITICO"))) | N19: Control de accesos | O19: PREVENTIVO | P19: Control Implementado sin evidencia de efectividad (Inefectivo prueba) | Q19: 0.3 | R19: Usuarios genéricos | S19: =+IF(O19="PREVENTIVO",J19*(1-Q19),IF(O19="ADMINISTRACION",J19*(1-Q19),IF(O19="ELIMINACION",J19*(1-Q19),J19))) | T19: =+IF(O19="DETECTIVO",K19*(1-Q19),IF(O19="RECUPERACION",K19*(1-Q19),K19)) | U19: =+S19*T19 | V19: =+IF(U19<5,"BAJO",IF(U19<10,"MEDIO",IF(U19<17,"ALTO","CRITICO"))) | W19: ACEPTABLE | X19: - | Y19: - | Z19: -
A20: 65-GTI | B20: Sendmail | C20: Administracion Contenidos y Correo electrónico | D20: [S] Servicios | E20: [A.5] Suplantación de la identidad del usuario | F20: =+VLOOKUP(E20,'CATALOGO AMENAZA'!$B$2:$D$46,3,FALSE) | G20: X | H20: X | J20: 2 | K20: 3 | L20: =+J20*K20 | M20: =+IF(L20<5,"BAJO",IF(L20<10,"MEDIO",IF(L20<17,"ALTO","CRITICO"))) | N20: Politicas de contraseñas robustas | O20: PREVENTIVO | P20: Control Implementado sin evidencia de efectividad (Inefectivo prueba) | Q20: 0.3 | R20: Usuarios genéricos / claves compartidas y almacenadas en navegadores | S20: =+IF(O20="PREVENTIVO",J20*(1-Q20),IF(O20="ADMINISTRACION",J20*(1-Q20),IF(O20="ELIMINACION",J20*(1-Q20),J20))) | T20: =+IF(O20="DETECTIVO",K20*(1-Q20),IF(O20="RECUPERACION",K20*(1-Q20),K20)) | U20: =+S20*T20 | V20: =+IF(U20<5,"BAJO",IF(U20<10,"MEDIO",IF(U20<17,"ALTO","CRITICO"))) | W20: ACEPTABLE | X20: - | Y20: - | Z20: -
A21: 65-GTI | B21: Sendmail | C21: Administracion Contenidos y Correo electrónico | D21: [S] Servicios | E21: [A.19] Divulgación de información | F21: =+VLOOKUP(E21,'CATALOGO AMENAZA'!$B$2:$D$46,3,FALSE) | G21: X | J21: 2 | K21: 3 | L21: =+J21*K21 | M21: =+IF(L21<5,"BAJO",IF(L21<10,"MEDIO",IF(L21<17,"ALTO","CRITICO"))) | N21: Validación de destinatarios | O21: PREVENTIVO | P21: Control Implementado sin evidencia de efectividad (Inefectivo prueba) | Q21: 0.3 | R21: Politicas sin restricción para jefaturas | S21: =+IF(O21="PREVENTIVO",J21*(1-Q21),IF(O21="ADMINISTRACION",J21*(1-Q21),IF(O21="ELIMINACION",J21*(1-Q21),J21))) | T21: =+IF(O21="DETECTIVO",K21*(1-Q21),IF(O21="RECUPERACION",K21*(1-Q21),K21)) | U21: =+S21*T21 | V21: =+IF(U21<5,"BAJO",IF(U21<10,"MEDIO",IF(U21<17,"ALTO","CRITICO"))) | W21: ACEPTABLE | X21: - | Y21: - | Z21: -
A22: 65-GTI | B22: Sendmail | C22: Administracion Contenidos y Correo electrónico | D22: [S] Servicios | E22: [A.24] Denegación de servicio | F22: =+VLOOKUP(E22,'CATALOGO AMENAZA'!$B$2:$D$46,3,FALSE) | I22: X | J22: 3 | K22: 4 | L22: =+J22*K22 | M22: =+IF(L22<5,"BAJO",IF(L22<10,"MEDIO",IF(L22<17,"ALTO","CRITICO"))) | N22: Software Antispam Fortimail | O22: PREVENTIVO | P22: Control Implementado sin evidencia de efectividad (Inefectivo prueba) | Q22: 0.3 | R22: No se realiza pruebas de carga | S22: =+IF(O22="PREVENTIVO",J22*(1-Q22),IF(O22="ADMINISTRACION",J22*(1-Q22),IF(O22="ELIMINACION",J22*(1-Q22),J22))) | T22: =+IF(O22="DETECTIVO",K22*(1-Q22),IF(O22="RECUPERACION",K22*(1-Q22),K22)) | U22: =+S22*T22 | V22: =+IF(U22<5,"BAJO",IF(U22<10,"MEDIO",IF(U22<17,"ALTO","CRITICO"))) | W22: MITIGAR | X22: - | Y22: - | Z22: -
A23: 65-GTI | B23: Sendmail | C23: Administracion Contenidos y Correo electrónico | D23: [S] Servicios | E23: [E.24] Caída del sistema por agotamiento de recursos | F23: =+VLOOKUP(E23,'CATALOGO AMENAZA'!$B$2:$D$46,3,FALSE) | I23: X | J23: 2 | K23: 3 | L23: =+J23*K23 | M23: =+IF(L23<5,"BAJO",IF(L23<10,"MEDIO",IF(L23<17,"ALTO","CRITICO"))) | N23: Monitoreo de Servidores presenta en el procedimiento operativo Administración de Servidores en el Manua de Gestión de las Operaciones de TI | O23: PREVENTIVO | P23: Control Implementado sin evidencia de efectividad (Inefectivo prueba) | Q23: 0.4 | R23: Falta de alertas automáticas | S23: =+IF(O23="PREVENTIVO",J23*(1-Q23),IF(O23="ADMINISTRACION",J23*(1-Q23),IF(O23="ELIMINACION",J23*(1-Q23),J23))) | T23: =+IF(O23="DETECTIVO",K23*(1-Q23),IF(O23="RECUPERACION",K23*(1-Q23),K23)) | U23: =+S23*T23 | V23: =+IF(U23<5,"BAJO",IF(U23<10,"MEDIO",IF(U23<17,"ALTO","CRITICO"))) | W23: ACEPTABLE | X23: - | Y23: - | Z23: -
A24: 66-GTI | B24: correo electronico | C24: Servidor web administracion correo electronico 192.168.23.2 | D24: [S] Servicios | E24: [A.11] Acceso no autorizado | F24: =+VLOOKUP(E24,'CATALOGO AMENAZA'!$B$2:$D$46,3,FALSE) | G24: X | H24: X | J24: 3 | K24: 3 | L24: =+J24*K24 | M24: =+IF(L24<5,"BAJO",IF(L24<10,"MEDIO",IF(L24<17,"ALTO","CRITICO"))) | N24: Control de accesos | O24: PREVENTIVO | P24: Control Implementado sin evidencia de efectividad (Inefectivo prueba) | Q24: 0.3 | R24: Usuarios genéricos | S24: =+IF(O24="PREVENTIVO",J24*(1-Q24),IF(O24="ADMINISTRACION",J24*(1-Q24),IF(O24="ELIMINACION",J24*(1-Q24),J24))) | T24: =+IF(O24="DETECTIVO",K24*(1-Q24),IF(O24="RECUPERACION",K24*(1-Q24),K24)) | U24: =+S24*T24 | V24: =+IF(U24<5,"BAJO",IF(U24<10,"MEDIO",IF(U24<17,"ALTO","CRITICO"))) | W24: MITIGAR | X24: - | Y24: - | Z24: -
